Workbook

Sheet ALL
A1: Humana Apparels Pvt. Ltd.
A2: Purchase Requisition
A3: Requisition No | E3: HAPL/Dept./ALL/2026/August/01 | N3: Store Personnel
A4: Requisition Date | E4: 46235 | N4: Md. Ebrahim
A5: Name of Unit | E5: Humana Apparels Pvt. Ltd. | N5: Sr. Executive
A6: Section | E6: ALL | N6: Store & Warehouse
A7: Name of User | E7: ALL | N7: 01839-004906
A8: Contact No. / Email | E8: amirul@humanaapparels.com | N8: ebrahim@humanaapparels.com
A9: SL | B9: Name of Item's | C9: Uom | D9: Specification / Brand & Model | E9: Type (Replace/ New) | F9: User Dept./ Section | G9: Stock Details | K9: Last Purchase Details | N9: To Be Procured | Q9: Store Acknowledgement on GRN | S9: Accounts Acknowledgement on Pmt | U9: Remarks
G10: Qty Requested | H10: Stock in Hand | I10: Saftey Stock | J10: Consumption (Last Month) | K10: Qty | L10: Approx Rate | M10: Date | N10: Qty | O10: Rate Appx. | P10: Amount | Q10: Pending Qty | R10: Signature | S10: Pending Qty | T10: Signature
A12: 1 | B12: Measurement Tape-Lace | C12: Pcs | E12: - | F12: Production/Sample/ Cad/Cutting | G12: 48 | H12: 36 | I12: =ROUND(J12/26*3,0) -> 7 | J12: 61 | K12: 150 | L12: 46 | M12: 46191 | N12: =G12-H12 -> 12 | O12: =L12 -> 46 | P12: =N12*O12 -> 552 | Q12: Production
A13: 2 | B13: Tailors Chalk | C13: Box | E13: - | F13: Production | G13: 180 | H13: 109 | I13: =ROUND(J13/26*3,0) -> 14 | J13: 118 | K13: 132 | L13: 6.4 | M13: 46221 | N13: =G13-H13 -> 71 | O13: =L13 -> 6.4 | P13: =N13*O13 -> 454.4 | Q13: Production
A14: 3 | B14: Binder Register Khata-16 | C14: Pcs | E14: - | F14: Production | G14: 28 | H14: 20 | I14: =ROUND(J14/26*3,0) -> 1 | J14: 5 | K14: 15 | L14: 290 | M14: 46193 | N14: =G14-H14 -> 8 | O14: =L14 -> 290 | P14: =N14*O14 -> 2320 | Q14: Stationary
A15: 4 | B15: Ball Pen-Black | C15: Pcs | E15: - | F15: All | G15: 336 | H15: 101 | I15: =ROUND(J15/26*3,0) -> 32 | J15: 279 | K15: 380 | L15: 5 | M15: 46222 | N15: =G15-H15 -> 235 | O15: =L15 -> 5 | P15: =N15*O15 -> 1175 | Q15: Stationary
A16: 5 | B16: Scissors QX-10" | C16: Pcs | E16: - | F16: Production | G16: 12 | H16: 7 | I16: =ROUND(J16/26*3,0) -> 1 | J16: 10 | K16: 6 | L16: 368 | M16: 46222 | N16: =G16-H16 -> 5 | O16: =L16 -> 368 | P16: =N16*O16 -> 1840 | Q16: Spare Parts
A17: 6 | B17: Thread Cutter | C17: Pcs | E17: - | F17: All | G17: 450 | H17: 50 | I17: =ROUND(J17/26*3,0) -> 59 | J17: 509 | K17: 540 | L17: 14.5 | M17: 46222 | N17: =G17-H17 -> 400 | O17: =L17 -> 14.5 | P17: =N17*O17 -> 5800 | Q17: Spare Parts
A18: 7 | B18: Masking Tape-01" | C18: Pcs | E18: - | F18: Production/Quilting | G18: 144 | H18: 74 | I18: =ROUND(J18/26*3,0) -> 25 | J18: 213 | K18: 161 | L18: 13.8 | M18: 46222 | N18: =G18-H18 -> 70 | O18: =L18 -> 13.8 | P18: =N18*O18 -> 966 | Q18: Production
A19: 8 | B19: Both Side Tape 01cm White | C19: Pcs | E19: - | F19: All | G19: 560 | H19: 372 | I19: =ROUND(J19/26*3,0) -> 34 | J19: 293 | K19: 336 | L19: 35.8 | M19: 46221 | N19: =G19-H19 -> 188 | O19: =L19 -> 35.8 | P19: =N19*O19 -> 6730.4 | Q19: Production
A20: 9 | B20: Gel Pen-Silver | C20: Pcs | E20: - | F20: Production/Cutting | G20: 250 | H20: 105 | I20: =ROUND(J20/26*3,0) -> 25 | J20: 217 | K20: 130 | L20: 16 | M20: 46229 | N20: =G20-H20 -> 145 | O20: =L20 -> 16 | P20: =N20*O20 -> 2320 | Q20: Stationary
A21: 10 | B21: P/M Plastic Plain Feet | C21: Pcs | E21: - | F21: Production | G21: 300 | H21: 110 | I21: =ROUND(J21/26*3,0) -> 24 | J21: 206 | K21: 186 | L21: 16 | M21: 46203 | N21: =G21-H21 -> 190 | O21: =L21 -> 16 | P21: =N21*O21 -> 3040 | Q21: Spare Parts
A22: 11 | B22: P/M Plastic Zipper Guide-Both | C22: Pcs | E22: - | F22: Production | G22: 100 | H22: 59 | I22: =ROUND(J22/26*3,0) -> 7 | J22: 60 | K22: 350 | L22: 18 | M22: 46079 | N22: =G22-H22 -> 41 | O22: =L22 -> 18 | P22: =N22*O22 -> 738 | Q22: Spare Parts
A23: 12 | B23: CD-DVD Marker Pen | C23: Pcs | E23: - | F23: All | G23: 150 | H23: 103 | I23: =ROUND(J23/26*3,0) -> 17 | J23: 144 | K23: 75 | L23: 17 | M23: 46221 | N23: =G23-H23 -> 47 | O23: =L23 -> 17 | P23: =N23*O23 -> 799 | Q23: Stationary
... A43: 32 | B43: Printer Cartridge-HP 45 | C43: Pcs | E43: - | F43: Sample +Cad | G43: 24 | H43: 9 | I43: =ROUND(J43/26*3,0) -> 2 | J43: 16 | K43: 7 | L43: 2940 | M43: 46232 | N43: =G43-H43 -> 15 | O43: =L43 -> 2940 | P43: =N43*O43 -> 44100 | Q43: Stationary
A44: 33 | B44: Stick Up Liquid Glue-50ml | C44: Pcs | D44: Deli | E44: - | F44: Sample +Cad | G44: 5 | H44: 0 | I44: =ROUND(J44/26*3,0) -> 1 | J44: 10 | K44: 4 | L44: 30 | M44: 46191 | N44: =G44-H44 -> 5 | O44: =L44 -> 30 | P44: =N44*O44 -> 150 | Q44: Stationary
A45: 34 | B45: Printer Cartridge-LBP 6030W | C45: Pcs | D45: 6030w | E45: - | F45: Sample Store | G45: 5 | H45: 3 | I45: =ROUND(J45/26*3,0) -> 0 | J45: 1 | K45: 4 | L45: 810 | M45: 46232 | N45: =G45-H45 -> 2 | O45: =L45 -> 810 | P45: =N45*O45 -> 1620 | Q45: Stationary
A46: 35 | B46: Poly-18" x 26" | C46: Kg | D46: Length 26", width 18" | E46: - | F46: Sample +Cad | G46: 10 | H46: 0 | I46: =ROUND(J46/26*3,0) -> 0 | J46: 0 | K46: 0 | L46: 0 | M46: 0 | N46: =G46-H46 -> 10 | O46: =L46 -> 0 | P46: =N46*O46 -> 0 | Q46: Stationary
A47: 36 | B47: Poly-28" x 22" | C47: KG | D47: Length 28", width 22" | E47: - | F47: Sample +Cad | G47: 10 | H47: 0 | I47: =ROUND(J47/26*3,0) -> 0 | J47: 0 | K47: 0 | L47: 0 | M47: 0 | N47: =G47-H47 -> 10 | O47: =L47 -> 0 | P47: =N47*O47 -> 0 | Q47: Stationary
A48: 37 | B48: Savlon | C48: Litter | E48: New | F48: Sample +Cad | G48: 5 | H48: 0 | I48: =ROUND(J48/26*3,0) -> 0 | J48: 0 | K48: 0 | L48: 0 | M48: 0 | N48: =G48-H48 -> 5 | O48: =L48 -> 0 | P48: =N48*O48 -> 0 | Q48: Stationary
A49: 38 | B49: Tibbat Ball Soap | C49: Pcs | D49: 570 | E49: - | F49: Sample +Cad | G49: 10 | H49: 0 | I49: =ROUND(J49/26*3,0) -> 2 | J49: 14 | K49: 14 | L49: 25 | M49: 46222 | N49: =G49-H49 -> 10 | O49: =L49 -> 25 | P49: =N49*O49 -> 250 | Q49: Production
A50: 39 | B50: EPSON Refill INK Bottle | C50: Pcs | D50: EPSON Ecotank (C=1,M=1,Y=1,K=1) | E50: New | F50: Sample +Cad | G50: 4 | H50: 0 | I50: =ROUND(J50/26*3,0) -> 0 | J50: 0 | K50: 0 | L50: 0 | M50: 0 | N50: =G50-H50 -> 4 | O50: =L50 -> 0 | P50: =N50*O50 -> 0 | Q50: Stationary
A51: 40 | B51: Laminating Paper-A4 Size | C51: Pkt | E51: - | F51: HR | G51: 2 | H51: 1 | I51: =ROUND(J51/26*3,0) -> 0 | J51: 0 | K51: 1 | L51: 780 | M51: 46222 | N51: =G51-H51 -> 1 | O51: =L51 -> 780 | P51: =N51*O51 -> 780 | Q51: Stationary
A52: 41 | B52: Staff ID Card | C52: Pcs | E52: - | F52: HR | G52: 300 | H52: 0 | I52: =ROUND(J52/26*3,0) -> 5 | J52: 43 | K52: 43 | L52: 42 | M52: 46224 | N52: =G52-H52 -> 300 | O52: =L52 -> 42 | P52: =N52*O52 -> 12600 | Q52: Press
A53: 42 | B53: NC Thinner | C53: Ltr | E53: - | F53: HR | G53: 8 | H53: 0 | I53: =ROUND(J53/26*3,0) -> 1 | J53: 8 | K53: 5 | L53: 250 | M53: 46221 | N53: =G53-H53 -> 8 | O53: =L53 -> 250 | P53: =N53*O53 -> 2000 | Q53: Chemical
A54: 43 | B54: Yellow Paint | C54: Galon | E54: - | F54: HR | G54: 2 | H54: 0 | I54: =ROUND(J54/26*3,0) -> 0 | J54: 2 | K54: 2 | L54: 4200 | M54: 46207 | N54: =G54-H54 -> 2 | O54: =L54 -> 4200 | P54: =N54*O54 -> 8400 | Q54: Cleaning
A55: 44 | B55: Red Paint | C55: Galon | E55: - | F55: HR | G55: 1 | H55: 0 | I55: =ROUND(J55/26*3,0) -> 0 | J55: 1 | K55: 1 | L55: 4200 | M55: 46207 | N55: =G55-H55 -> 1 | O55: =L55 -> 4200 | P55: =N55*O55 -> 4200 | Q55: Stationary
A56: 45 | B56: Gum Tape 01" Transparent | C56: Pcs | E56: - | F56: All | G56: 560 | H56: 292 | I56: =ROUND(J56/26*3,0) -> 48 | J56: 417 | K56: 260 | L56: 12 | M56: 46221 | N56: =G56-H56 -> 268 | O56: =L56 -> 12 | P56: =N56*O56 -> 3216 | Q56: Production
A57: 46 | B57: Ear Plug | C57: Pcs | E57: - | F57: HR | G57: 20 | H57: 0 | I57: =ROUND(J57/26*3,0) -> 0 | J57: 0 | K57: 29 | L57: 15 | M57: 45434 | N57: =G57-H57 -> 20 | O57: =L57 -> 15 | P57: =N57*O57 -> 300 | Q57: Stationary
A58: 47 | B58: Binder Clip-32mm | C58: Pcs | D58: Small Size | E58: - | F58: HR | G58: 60 | H58: 0 | I58: =ROUND(J58/26*3,0) -> 3 | J58: 24 | K58: 25 | L58: 4 | M58: 45936 | N58: =G58-H58 -> 60 | O58: =L58 -> 4 | P58: =N58*O58 -> 240 | Q58: Stationary
A59: 48 | B59: Mineral Water-330ml | C59: Pcs | D59: MUM | E59: - | F59: HR | G59: =24*5 -> 120 | H59: 0 | I59: =ROUND(J59/26*3,0) -> 8 | J59: 72 | K59: 72 | L59: 9.791 | M59: 46212 | N59: =G59-H59 -> 120 | O59: =L59 -> 9.791 | P59: =N59*O59 -> 1174.92 | Q59: Cleaning
A60: 49 | B60: Battary | C60: Pcs | D60: Colling Bell Remort | E60: New | F60: HR | G60: 6 | H60: 0 | I60: =ROUND(J60/26*3,0) -> 0 | J60: 0 | K60: 0 | L60: 0 | M60: 0 | N60: =G60-H60 -> 6 | O60: =L60 -> 0 | P60: =N60*O60 -> 0 | Q60: Stationary
...

Sheet Stationary
A1: Humana Apparels Pvt Ltd.
A2: Purchase Requisition
A3: Requisition No | E3: =ALL!E3 -> HAPL/Dept./ALL/2026/August/01 | N3: Store Personnel
A4: Requisition Date | E4: =ALL!E4 -> 46235 | N4: Md. Ebrahim
A5: Name of Unit | E5: =ALL!E5 -> Humana Apparels Pvt. Ltd. | N5: Sr. Executive
A6: Section | E6: =ALL!E6 -> ALL | N6: Store & Warehouse
A7: Name of User | E7: =ALL!E7 -> ALL | N7: 01839-004906
A8: Contact No. / Email | E8: =ALL!E8 -> amirul@humanaapparels.com | N8: ebrahim@humanaapparels.com
A9: SL | B9: Name of Item's | C9: Uom | D9: Specification / Brand & Model | E9: Type (Replace/ New) | F9: User Dept./ Section | G9: Stock Details | K9: Last Purchase Details | N9: To Be Procured | Q9: Store Acknowledgement on GRN | S9: Accounts Acknowledgment on Pmt | U9: Remarks
G10: Qty Requested | H10: Stock in Hand | I10: Saftey Stock | J10: Consumption (Last Month) | K10: Qty | L10: Approx Rate | M10: Date | N10: Qty | O10: Rate Appx. | P10: Amount | Q10: Pending Qty | R10: Signature | S10: Pending Qty | T10: Signature
A11: 1 | B11: Binder Register Khata-16 | C11: Pcs | E11: - | F11: Production | G11: 28 | H11: 20 | I11: 1 | J11: 5 | K11: 15 | L11: 290 | M11: 46193 | N11: 8 | O11: 290 | P11: 2320
A12: 2 | B12: Ball Pen-Black | C12: Pcs | E12: - | F12: All | G12: 336 | H12: 101 | I12: 32 | J12: 279 | K12: 380 | L12: 5 | M12: 46222 | N12: 235 | O12: 5 | P12: 1175
A13: 3 | B13: Gel Pen-Silver | C13: Pcs | E13: - | F13: Production/Cutting | G13: 250 | H13: 105 | I13: 25 | J13: 217 | K13: 130 | L13: 16 | M13: 46229 | N13: 145 | O13: 16 | P13: 2320
A14: 4 | B14: CD-DVD Marker Pen | C14: Pcs | E14: - | F14: All | G14: 150 | H14: 103 | I14: 17 | J14: 144 | K14: 75 | L14: 17 | M14: 46221 | N14: 47 | O14: 17 | P14: 799
A15: 5 | B15: Ereasser/Rubber | C15: Pcs | E15: - | F15: All | G15: 160 | H15: 92 | I15: 13 | J15: 115 | K15: 163 | L15: 5 | M15: 46221 | N15: 68 | O15: 5 | P15: 340
A16: 6 | B16: Pencil Cutter/ Sharpner | C16: Pcs | E16: - | F16: All | G16: 72 | H16: 39 | I16: 6 | J16: 51 | K16: 60 | L16: 5 | M16: 46222 | N16: 33 | O16: 5 | P16: 165
A17: 7 | B17: Calculator CD-120 | C17: Pcs | E17: - | F17: Store Production | G17: 6 | H17: 0 | I17: 1 | J17: 9 | K17: 4 | L17: 390 | M17: 46222 | N17: 6 | O17: 390 | P17: 2340
A18: 8 | B18: Offset Paper-A4 Size | C18: Ream | E18: - | F18: All | G18: 102 | H18: 61 | I18: 10 | J18: 86 | K18: 123 | L18: 430 | M18: 46222 | N18: 41 | O18: 430 | P18: 17630
A19: 9 | B19: Tooth Brush | C19: Pcs | E19: - | F19: Production/Finishing | G19: 24 | H19: 10 | I19: 2 | J19: 14 | K19: 3 | L19: 10 | M19: 46221 | N19: 14 | O19: 10 | P19: 140
A20: 10 | B20: Ball Pen-Red | C20: Pcs | E20: - | F20: Sample+Cad/Account | G20: 16 | H20: 0 | I20: 0 | J20: 0 | K20: 6 | L20: 4.85 | M20: 46153 | N20: 16 | O20: 4.85 | P20: 77.6
A21: 11 | B21: Printer Cartridge-HP 45 | C21: Pcs | E21: - | F21: Sample +Cad | G21: 24 | H21: 9 | I21: 2 | J21: 16 | K21: 7 | L21: 2940 | M21: 46232 | N21: 15 | O21: 2940 | P21: 44100
A22: 12 | B22: Stick Up Liquid Glue-50ml | C22: Pcs | D22: Deli | E22: - | F22: Sample +Cad | G22: 5 | H22: 0 | I22: 1 | J22: 10 | K22: 4 | L22: 30 | M22: 46191 | N22: 5 | O22: 30 | P22: 150
A23: 13 | B23: Printer Cartridge-LBP 6030W | C23: Pcs | D23: 6030w | E23: - | F23: Sample Store | G23: 5 | H23: 3 | I23: 0 | J23: 1 | K23: 4 | L23: 810 | M23: 46232 | N23: 2 | O23: 810 | P23: 1620
A24: 14 | B24: Poly-18" x 26" | C24: Kg | D24: Length 26", width 18" | E24: - | F24: Sample +Cad | G24: 10 | H24: 0 | I24: 0 | J24: 0 | K24: 0 | L24: 0 | M24: 0 | N24: 10 | O24: 0 | P24: 0
A25: 15 | B25: Poly-28" x 22" | C25: KG | D25: Length 28", width 22" | E25: - | F25: Sample +Cad | G25: 10 | H25: 0 | I25: 0 | J25: 0 | K25: 0 | L25: 0 | M25: 0 | N25: 10 | O25: 0 | P25: 0
A26: 16 | B26: Savlon | C26: Litter | E26: New | F26: Sample +Cad | G26: 5 | H26: 0 | I26: 0 | J26: 0 | K26: 0 | L26: 0 | M26: 0 | N26: 5 | O26: 0 | P26: 0
A27: 17 | B27: EPSON Refill INK Bottle | C27: Pcs | D27: EPSON Ecotank (C=1,M=1,Y=1,K=1) | E27: New | F27: Sample +Cad | G27: 4 | H27: 0 | I27: 0 | J27: 0 | K27: 0 | L27: 0 | M27: 0 | N27: 4 | O27: 0 | P27: 0
A28: 18 | B28: Laminating Paper-A4 Size | C28: Pkt | E28: - | F28: HR | G28: 2 | H28: 1 | I28: 0 | J28: 0 | K28: 1 | L28: 780 | M28: 46222 | N28: 1 | O28: 780 | P28: 780
A29: 19 | B29: Red Paint | C29: Galon | E29: - | F29: HR | G29: 1 | H29: 0 | I29: 0 | J29: 1 | K29: 1 | L29: 4200 | M29: 46207 | N29: 1 | O29: 4200 | P29: 4200
A30: 20 | B30: Ear Plug | C30: Pcs | E30: - | F30: HR | G30: 20 | H30: 0 | I30: 0 | J30: 0 | K30: 29 | L30: 15 | M30: 45434 | N30: 20 | O30: 15 | P30: 300
A31: 21 | B31: Binder Clip-32mm | C31: Pcs | D31: Small Size | E31: - | F31: HR | G31: 60 | H31: 0 | I31: 3 | J31: 24 | K31: 25 | L31: 4 | M31: 45936 | N31: 60 | O31: 4 | P31: 240
A32: 22 | B32: Battary | C32: Pcs | D32: Colling Bell Remort | E32: New | F32: HR | G32: 6 | H32: 0 | I32: 0 | J32: 0 | K32: 0 | L32: 0 | M32: 0 | N32: 6 | O32: 0 | P32: 0
A33: 23 | B33: Marker Pen-Permanent | C33: Pcs | E33: - | F33: Finishing/Cutting/Store | G33: 72 | H33: 25 | I33: 3 | J33: 27 | K33: 10 | L33: 33 | M33: 46222 | N33: 47 | O33: 33 | P33: 1551
A34: 24 | B34: Denim Pen-56 | C34: Pcs | E34: New | F34: Finishing | G34: 6 | H34: 0 | I34: 0 | J34: 0 | K34: 0 | L34: 0 | M34: 0 | N34: 6 | O34: 0 | P34: 0
A35: 25 | B35: Color Mix Bati | C35: Pcs | D35: Plastic | E35: New | F35: Finishing | G35: 10 | H35: 0 | I35: 0 | J35: 0 | K35: 0 | L35: 0 | M35: 0 | N35: 10 | O35: 0 | P35: 0
A36: 26 | B36: Printer Cartridge-87 A | C36: Pcs | D36: TCH-CF287A | E36: - | F36: Finishing | G36: 3 | H36: 0 | I36: 0 | J36: 2 | K36: 1 | L36: 810 | M36: 46201 | N36: 3 | O36: 810 | P36: 2430
A37: 27 | B37: Hi-Light Pen-Yellow | C37: Pcs | E37: - | F37: Account Production | G37: 20 | H37: 8 | I37: 2 | J37: 16 | K37: 32 | L37: 28 | M37: 46123 | N37: 12 | O37: 28 | P37: 336
A38: 28 | B38: Paper Weight | C38: Pcs | E38: - | F38: Account | G38: 5 | H38: 0 | I38: 0 | J38: 0 | K38: 5 | L38: 150 | M38: 45826 | N38: 5 | O38: 150 | P38: 750
A39: 29 | B39: Hi-Light Pen-Green | C39: Pcs | D39: Matador | E39: - | F39: Cutting | G39: 12 | H39: 1 | I39: 2 | J39: 14 | K39: 5 | L39: 28 | M39: 46222 | N39: 11 | O39: 28 | P39: 308
A40: 30 | B40: C/M Numbering Ink-Silver | C40: Pcs | D40: Pione | E40: - | F40: Cutting | G40: 5 | H40: 4 | I40: 0 | J40: 1 | K40: 1 | L40: 750 | M40: 46221 | N40: 1 | O40: 750 | P40: 750
...

Sheet Production
A1: Humana Apparels Pvt Ltd.
A2: Purchase Requisition
A3: Requisition No | E3: =ALL!E3 -> HAPL/Dept./ALL/2026/August/01 | N3: Store Personnel
A4: Requisition Date | E4: =ALL!E4 -> 46235 | N4: Md. Ebrahim
A5: Name of Unit | E5: =ALL!E5 -> Humana Apparels Pvt. Ltd. | N5: Sr. Executive
A6: Section | E6: =ALL!E6 -> ALL | N6: Store & Warehouse
A7: Name of User | E7: =ALL!E7 -> ALL | N7: 01839-004906
A8: Contact No. / Email | E8: =ALL!E8 -> amirul@humanaapparels.com | N8: ebrahim@humanaapparels.com
A9: SL | B9: Name of Item's | C9: Uom | D9: Specification / Brand & Model | E9: Type (Replace/ New) | F9: User Dept./ Section | G9: Stock Details | K9: Last Purchase Details | N9: To Be Procured | Q9: Store Acknowledgement on GRN | S9: Accounts Acknowledgment on Pmt | U9: Remarks
G10: Qty Requested | H10: Stock in Hand | I10: Saftey Stock | J10: Consumption (Last Month) | K10: Qty | L10: Approx Rate | M10: Date | N10: Qty | O10: Rate Appx. | P10: Amount | Q10: Pending Qty | R10: Signature | S10: Pending Qty | T10: Signature
A11: 1 | B11: Measurement Tape-Lace | C11: Pcs | E11: - | F11: Production/Sample/ Cad/Cutting | G11: 48 | H11: 36 | I11: 7 | J11: 61 | K11: 150 | L11: 46 | M11: 46191 | N11: 12 | O11: 46 | P11: 552
A12: 2 | B12: Tailors Chalk | C12: Box | E12: - | F12: Production | G12: 180 | H12: 109 | I12: 14 | J12: 118 | K12: 132 | L12: 6.4 | M12: 46221 | N12: 71 | O12: 6.4 | P12: 454.4
A13: 3 | B13: Masking Tape-01" | C13: Pcs | E13: - | F13: Production/Quilting | G13: 144 | H13: 74 | I13: 25 | J13: 213 | K13: 161 | L13: 13.8 | M13: 46222 | N13: 70 | O13: 13.8 | P13: 966
A14: 4 | B14: Both Side Tape 01cm White | C14: Pcs | E14: - | F14: All | G14: 560 | H14: 372 | I14: 34 | J14: 293 | K14: 336 | L14: 35.8 | M14: 46221 | N14: 188 | O14: 35.8 | P14: 6730.4
A15: 5 | B15: Foam Tape-3.4 Feet | C15: Pcs | E15: - | F15: Production/Quilting | G15: 1300 | H15: 170 | I15: 115 | J15: 1000 | K15: 1400 | L15: 15 | M15: 46193 | N15: 1130 | O15: 15 | P15: 16950
A16: 6 | B16: Pvc Sheet (6'X3')-0.5mm | C16: Pcs | E16: - | F16: Production | G16: 60 | H16: 36 | I16: 1 | J16: 12 | K16: 9 | L16: 600 | M16: 46153 | N16: 24 | O16: 600 | P16: 14400
A17: 7 | B17: shead label a- h per size 600pies | C17: Pcs | E17: - | F17: Production | G17: 5000 | H17: 0 | I17: 0 | J17: 0 | K17: 0 | L17: 0 | M17: 0 | N17: 5000 | O17: 0 | P17: 0
A18: 8 | B18: avaalble size label xs .s.m.l.xl.xxl per size 200 | C18: Pcs | E18: - | F18: Production | G18: 1200 | H18: 0 | I18: 0 | J18: 0 | K18: 0 | L18: 0 | M18: 0 | N18: 1200 | O18: 0 | P18: 0
A19: 9 | B19: Both side fusing interlining | C19: Pcs | E19: - | F19: Production | G19: 2 | H19: 0 | I19: 0 | J19: 0 | K19: 0 | L19: 0 | M19: 0 | N19: 2 | O19: 0 | P19: 0
A20: 10 | B20: interlining biskut item 1060 (for pin hole ) rotex bd | C20: Pcs | E20: - | F20: Production | G20: 2 | H20: 0 | I20: 0 | J20: 0 | K20: 0 | L20: 0 | M20: 0 | N20: 2 | O20: 0 | P20: 0
A21: 11 | B21: Poly-50 x 70 cm | C21: Kg | E21: - | F21: Production | G21: 20 | H21: 0 | I21: 0 | J21: 0 | K21: 2.3 | L21: 478.26 | M21: 46193 | N21: 20 | O21: 478.26 | P21: 9565.2
A22: 12 | B22: Poly-80 x 90 cm | C22: Kg | E22: - | F22: Production | G22: 20 | H22: 0 | I22: 0 | J22: 0 | K22: 33.75 | L22: 355.55 | M22: 46163 | N22: 20 | O22: 355.55 | P22: 7111
... A24: 14 | B24: Marker Paper (Intake)-64" | C24: Kg | E24: - | F24: Sample+Cad | G24: 2000 | H24: 804.1 | I24: 73 | J24: 635 | K24: 904.7 | L24: 68 | M24: 46198 | N24: 1195.9 | O24: 68 | P24: 81321.2
A25: 15 | B25: Tibbat Ball Soap | C25: Pcs | D25: 570 | E25: - | F25: Sample +Cad | G25: 10 | H25: 0 | I25: 2 | J25: 14 | K25: 14 | L25: 25 | M25: 46222 | N25: 10 | O25: 25 | P25: 250
A26: 16 | B26: Gum Tape 01" Transparent | C26: Pcs | E26: - | F26: All | G26: 560 | H26: 292 | I26: 48 | J26: 417 | K26: 260 | L26: 12 | M26: 46221 | N26: 268 | O26: 12 | P26: 3216
A27: 17 | B27: Adhesive Paper-A4 Size-Brown | C27: Pkt | D27: Must be Printing Page | E27: - | F27: Finishing | G27: 30 | H27: 5 | I27: 1 | J27: 5 | K27: 10 | L27: 595 | M27: 46224 | N27: 25 | O27: 595 | P27: 14875
A28: 18 | B28: Denim Pen-82 | C28: Pcs | E28: - | F28: Finishing | G28: 6 | H28: 0 | I28: 0 | J28: 2 | K28: 2 | L28: 180 | M28: 46190 | N28: 6 | O28: 180 | P28: 1080
A29: 19 | B29: Single Jersy Fabrics | C29: Kg | D29: Single Jersey | E29: - | F29: Cutting | G29: 500 | H29: 418.1 | I29: 35 | J29: 300 | K29: 418.1 | L29: 220 | M29: 46228 | N29: 81.9 | O29: 220 | P29: 18018
A30: 20 | B30: Marker Paper (Loose)-64" | C30: Kg | D30: 64 Inch | E30: - | F30: Cutting | G30: 1000 | H30: 591 | I30: 71 | J30: 614 | K30: 419 | L30: 68 | M30: 46221 | N30: 409 | O30: 68 | P30: 27812
A31: 21 | B31: Kerosene Oil | C31: Ltr | E31: - | F31: Cutting | G31: 10 | H31: 0 | I31: 1 | J31: 10 | K31: 5 | L31: 170 | M31: 46222 | N31: 10 | O31: 170 | P31: 1700
A32: 22 | B32: Finger Balloon | C32: Pcs | D32: Scent-free balloon (Good Quality) | E32: - | F32: Cutting | G32: 1000 | H32: 667 | I32: 58 | J32: 500 | K32: 600 | L32: 2.5 | M32: 46222 | N32: 333 | O32: 2.5 | P32: 832.5
A33: 23 | B33: Gum Tape 2.5" Transparent | C33: Pcs | D33: 2.5 Inch | E33: - | F33: Cutting | G33: 400 | H33: 272 | I33: 55 | J33: 474 | K33: 591 | L33: 27 | M33: 46221 | N33: 128 | O33: 27 | P33: 3456
A34: 24 | B34: Cutting Knife-10" | C34: Pcs | D34: 10 Inch | E34: - | F34: Cutting | G34: 60 | H34: 24 | I34: 2 | J34: 13 | K34: 24 | L34: 42 | M34: 46167 | N34: 36 | O34: 42 | P34: 1512
A35: 25 | B35: Numbering Cutting Tuly | C35: Pcs | E35: - | F35: Cutting | G35: 50 | H35: 0 | I35: 5 | J35: 46 | K35: 51 | L35: 6 | M35: 46193 | N35: 50 | O35: 6 | P35: 300
A36: 26 | B36: C/M Numbering Sticker-Medium | C36: Pcs | D36: Prokash (Medium Gum) | E36: - | F36: Cutting | G36: 500 | H36: 100 | I36: 30 | J36: 260 | K36: 160 | L36: 17 | M36: 46191 | N36: 400 | O36: 17 | P36: 6800
A37: 27 | B37: C/M Sticker Ink/Blitz Ink | C37: Pcs | D37: Blidz ( Roller) | E37: - | F37: Cutting | G37: 20 | H37: 11 | I37: 1 | J37: 10 | K37: 10 | L37: 95 | M37: 46222 | N37: 9 | O37: 95 | P37: 855
A38: 28 | B38: Abrasive Belt | C38: Box | D38: KM (Abrasive Belts) Original | E38: - | F38: Cutting | G38: 15 | H38: 9 | I38: 1 | J38: 7 | K38: 5 | L38: 350 | M38: 46222 | N38: 6 | O38: 350 | P38: 2100
A39: 29 | B39: Polyethene -72" | C39: Pound | D39: Width 60" (30 Micron) | E39: - | F39: Cutting | G39: 50 | H39: 48 | I39: 0 | J39: 0 | K39: 48 | L39: 65 | M39: 46191 | N39: 2 | O39: 65 | P39: 130
A40: 30 | B40: Poly-40x35" | C40: Kg | E40: - | F40: Cutting | G40: 50 | H40: 31.751 | I40: 0 | J40: 0 | K40: 31.751 | L40: 418.88 | M40: 46222 | N40: 18.249 | O40: 418.88 | P40: 7644.1411
A41: 31 | B41: Poly-26x42" | C41: Kg | E41: - | F41: Cutting | G41: 50 | H41: 34.772 | I41: 2 | J41: 19.479 | K41: 31.751 | L41: 440.93 | M41: 46222 | N41: 15.228 | O41: 440.93 | P41: 6714.482
...

Sheet Cleaning
A1: Humana Apparels Pvt Ltd.
A2: Purchase Requisition
A3: Requisition No | E3: =ALL!E3 -> HAPL/Dept./ALL/2026/August/01 | N3: Store Personnel
A4: Requisition Date | E4: =ALL!E4 -> 46235 | N4: Md. Ebrahim
A5: Name of Unit | E5: =ALL!E5 -> Humana Apparels Pvt. Ltd. | N5: Sr. Executive
A6: Section | E6: =ALL!E6 -> ALL | N6: Store & Warehouse
A7: Name of User | E7: =ALL!E7 -> ALL | N7: 01839-004906
A8: Contact No. / Email | E8: =ALL!E8 -> amirul@humanaapparels.com | N8: ebrahim@humanaapparels.com
A9: SL | B9: Name of Item's | C9: Uom | D9: Specification / Brand & Model | E9: Type (Replace/ New) | F9: User Dept./ Section | G9: Stock Details | K9: Last Purchase Details | N9: To Be Procured | Q9: Store Acknowledgement on GRN | S9: Accounts Acknowledgment on Pmt | U9: Remarks
G10: Qty Requested | H10: Stock in Hand | I10: Saftey Stock | J10: Consumption (Last Month) | K10: Qty | L10: Approx Rate | M10: Date | N10: Qty | O10: Rate Appx. | P10: Amount | Q10: Pending Qty | R10: Signature | S10: Pending Qty | T10: Signature
A11: 1 | B11: Yellow Paint | C11: Galon | E11: - | F11: HR | G11: 2 | H11: 0 | I11: 0 | J11: 2 | K11: 2 | L11: 4200 | M11: 46207 | N11: 2 | O11: 4200 | P11: 8400
A12: 2 | B12: Mineral Water-330ml | C12: Pcs | D12: MUM | E12: - | F12: HR | G12: 120 | H12: 0 | I12: 8 | J12: 72 | K12: 72 | L12: 9.791 | M12: 46212 | N12: 120 | O12: 9.791 | P12: 1174.92
A13: 3 | B13: Broom Flower | C13: Pcs | E13: - | F13: Cleaning | G13: 60 | H13: 50 | I13: 2 | J13: 20 | K13: 70 | L13: 50 | M13: 46222 | N13: 10 | O13: 50 | P13: 500
A14: 4 | B14: Napkin Tissue | C14: Pkt | D14: Fresh Soft | E14: - | F14: Cleaning | G14: 40 | H14: 28 | I14: 6 | J14: 48 | K14: 42 | L14: 70 | M14: 46222 | N14: 12 | O14: 70 | P14: 840
A15: 5 | B15: Harpic Liquid-750ml | C15: Pcs | E15: - | F15: Cleaning | G15: 200 | H15: 126 | I15: 11 | J15: 92 | K15: 200 | L15: 109.5 | M15: 46221 | N15: 74 | O15: 109.5 | P15: 8103
A16: 6 | B16: Lizol Floor Cleaner-1000ml | C16: Pcs | E16: - | F16: Cleaning | G16: 25 | H16: 18 | I16: 3 | J16: 30 | K16: 48 | L16: 265 | M16: 46222 | N16: 7 | O16: 265 | P16: 1855
A17: 7 | B17: Vim Dishwashing Liquid 500ml | C17: Pcs | E17: - | F17: Cleaning | G17: 30 | H17: 14 | I17: 2 | J17: 19 | K17: 24 | L17: 130 | M17: 46221 | N17: 16 | O17: 130 | P17: 2080
A18: 8 | B18: Hand Towel Tissue | C18: Pcs | E18: - | F18: Cleaning | G18: 5 | H18: 4 | I18: 0 | J18: 2 | K18: 6 | L18: 100 | M18: 46221 | N18: 1 | O18: 100 | P18: 100
A19: 9 | B19: Handwash Liquied 5ltr Jar | C19: Pcs | D19: Life Boy | E19: - | F19: Cleaning | G19: 2 | H19: 1 | I19: 0 | J19: 1 | K19: 1 | L19: 1100 | M19: 46221 | N19: 1 | O19: 1100 | P19: 1100
A20: 10 | B20: Mop Small Size | C20: Pcs | E20: - | F20: Cleaning | G20: 10 | H20: 0 | I20: 0 | J20: 0 | K20: 0 | L20: 0 | M20: 0 | N20: 10 | O20: 0 | P20: 0
A21: 11 | B21: Wheel Detergent Powder | C21: Kg | E21: - | F21: Cleaning | G21: 15 | H21: 0 | I21: 2 | J21: 19 | K21: 14 | L21: 140 | M21: 46191 | N21: 15 | O21: 140 | P21: 2100
A22: 12 | B22: Bleaching Powder | C22: Kg | E22: - | F22: Cleaning | G22: 15 | H22: 0 | I22: 2 | J22: 18 | K22: 11 | L22: 70 | M22: 46221 | N22: 15 | O22: 70 | P22: 1050
A23: 13 | B23: Phenyle Floor Cleaner (3 Ltr Jar) | C23: Pcs | D23: 05 Ltt Jar | E23: - | F23: Cleaning | G23: 10 | H23: 5 | I23: 1 | J23: 6 | K23: 11 | L23: 170 | M23: 46222 | N23: 5 | O23: 170 | P23: 850
A24: 14 | B24: Toilet Tissue | C24: Pcs | D24: Bashundara | E24: - | F24: Cleaning | G24: 360 | H24: 240 | I24: 17 | J24: 149 | K24: 317 | L24: 21.8 | M24: 46222 | N24: 120 | O24: 21.8 | P24: 2616
A25: 15 | B25: Toilet Hand Brush | C25: Pcs | D25: Toilet Round Broush | E25: - | F25: Cleaning | G25: 20 | H25: 0 | I25: 1 | J25: 12 | K25: 12 | L25: 65 | M25: 46191 | N25: 20 | O25: 65 | P25: 1300
A26: 16 | B26: Cosco Soap-Mini | C26: Pcs | E26: - | F26: Cleaning | G26: 300 | H26: 230 | I26: 33 | J26: 288 | K26: 216 | L26: 14.6 | M26: 46221 | N26: 70 | O26: 14.6 | P26: 1022
A27: 17 | B27: Odonil Air Freshner | C27: Pcs | D27: Jesmin | E27: - | F27: Cleaning | G27: 30 | H27: 14 | I27: 2 | J27: 19 | K27: 26 | L27: 45 | M27: 46221 | N27: 16 | O27: 45 | P27: 720
A28: 18 | B28: Naphthalene | C28: Kg | E28: - | F28: Cleaning | G28: 3 | H28: 0 | I28: 0 | J28: 4 | K28: 2 | L28: 390 | M28: 46222 | N28: 3 | O28: 390 | P28: 1170
A29: 19 | B29: Glass Cleaner-350ml | C29: Pcs | E29: - | F29: Cleaning | G29: 10 | H29: 0 | I29: 1 | J29: 11 | K29: 11 | L29: 95 | M29: 46221 | N29: 10 | O29: 95 | P29: 950
A30: 20 | B30: Vixol Power-1000ml | C30: Pcs | E30: - | F30: Cleaning | G30: 15 | H30: 10 | I30: 1 | J30: 7 | K30: 10 | L30: 85 | M30: 46222 | N30: 5 | O30: 85 | P30: 425
A31: 21 | B31: Washroom Uses Sandle | C31: Pair | E31: - | F31: Cleaning | G31: 40 | H31: 0 | I31: 7 | J31: 62 | K31: 59 | L31: 40 | M31: 46221 | N31: 40 | O31: 40 | P31: 1600
A32: 22 | B32: Connection Pipe-48" | C32: Pcs | D32: 48" | E32: - | F32: Cleaning | G32: 10 | H32: 7 | I32: 0 | J32: 0 | K32: 12 | L32: 100 | M32: 45556 | N32: 3 | O32: 100 | P32: 300
A33: 23 | B33: Drwar Lock | C33: Pcs | E33: New | F33: Cleaning | G33: 60 | H33: 0 | I33: 0 | J33: 0 | K33: 0 | L33: 0 | M33: 0 | N33: 60 | O33: 0 | P33: 0
A34: 24 | B34: Garbage Polybag | C34: Kg | E34: - | F34: Cleaning | G34: 4 | H34: 3 | I34: 0 | J34: 0 | K34: 3 | L34: 210 | M34: 46222 | N34: 1 | O34: 210 | P34: 210
A35: 25 | B35: Surgical Face Mask | C35: Pkt | D35: Sepnil | E35: - | F35: Cutting/Quilting | G35: 50 | H35: 31 | I35: 3 | J35: 25 | K35: 18 | L35: 220 | M35: 46229 | N35: 19 | O35: 220 | P35: 4180
A36: Total- | P36: =SUM(P11:P35) -> 42645.92
B43: Prepared by | G43: Store | O43: Checked by | T43: Approved by

Sheet Press
A1: Humana Apparels Pvt Ltd.
A2: Purchase Requisition
A3: Requisition No | E3: =ALL!E3 -> HAPL/Dept./ALL/2026/August/01 | N3: Store Personnel
A4: Requisition Date | E4: =ALL!E4 -> 46235 | N4: Md. Ebrahim
A5: Name of Unit | E5: =ALL!E5 -> Humana Apparels Pvt. Ltd. | N5: Sr. Executive
A6: Section | E6: =ALL!E6 -> ALL | N6: Store & Warehouse
A7: Name of User | E7: =ALL!E7 -> ALL | N7: 01839-004906
A8: Contact No. / Email | E8: =ALL!E8 -> amirul@humanaapparels.com | N8: ebrahim@humanaapparels.com
A9: SL | B9: Name of Item's | C9: Uom | D9: Specification / Brand & Model | E9: Type (Replace/ New) | F9: User Dept./ Section | G9: Stock Details | K9: Last Purchase Details | N9: To Be Procured | Q9: Store Acknowledgement on GRN | S9: Accounts Acknowledgment on Pmt | U9: Remarks
G10: Qty Requested | H10: Stock in Hand | I10: Saftey Stock | J10: Consumption (Last Month) | K10: Qty | L10: Approx Rate | M10: Date | N10: Qty | O10: Rate Appx. | P10: Amount | Q10: Pending Qty | R10: Signature | S10: Pending Qty | T10: Signature
A11: 1 | B11: Staff ID Card | C11: Pcs | E11: - | F11: HR | G11: 300 | H11: 0 | I11: 5 | J11: 43 | K11: 43 | L11: 42 | M11: 46224 | N11: 300 | O11: 42 | P11: 12600
A12: 2 | B12: Cutting Quality Control Report | C12: Book | D12: 100 page | E12: - | F12: Cutting | G12: 20 | H12: 0 | I12: 0 | J12: 0 | K12: 30 | L12: 65 | M12: 45566 | N12: 20 | O12: 65 | P12: 1300
A13: 3 | B13: Lay Report Book | C13: Book | D13: 100 page | E13: - | F13: Cutting | G13: 30 | H13: 0 | I13: 0 | J13: 0 | K13: 40 | L13: 68.25 | M13: 45859 | N13: 30 | O13: 68.25 | P13: 2047.5
A14: 4 | B14: Bin Card | C14: Pcs | E14: - | F14: Store | G14: 1000 | H14: 0 | I14: 115 | J14: 1000 | K14: 1000 | L14: 2.62 | M14: 46083 | N14: 1000 | O14: 2.62 | P14: 2620
A15: Total- | P15: =SUM(P11:P14) -> 18567.5
B24: Prepared by | G24: Store | O24: Checked by | T24: Approved by

Sheet Medical
A1: Humana Apparels Pvt Ltd.
A2: Purchase Requisition
A3: Requisition No | E3: =ALL!E3 -> HAPL/Dept./ALL/2026/August/01 | N3: Store Personnel
A4: Requisition Date | E4: =ALL!E4 -> 46235 | N4: Md. Ebrahim
A5: Name of Unit | E5: =ALL!E5 -> Humana Apparels Pvt. Ltd. | N5: Sr. Executive
A6: Section | E6: =ALL!E6 -> ALL | N6: Store & Warehouse
A7: Name of User | E7: =ALL!E7 -> ALL | N7: 01839-004906
A8: Contact No. / Email | E8: =ALL!E8 -> amirul@humanaapparels.com | N8: ebrahim@humanaapparels.com
A9: SL | B9: Name of Item's | C9: Uom | D9: Specification / Brand & Model | E9: Type (Replace/ New) | F9: User Dept./ Section | G9: Stock Details | K9: Last Purchase Details | N9: To Be Procured | Q9: Store Acknowledgement on GRN | S9: Accounts Acknowledgment on Pmt | U9: Remarks
G10: Qty Requested | H10: Stock in Hand | I10: Saftey Stock | J10: Consumption (Last Month) | K10: Qty | L10: Approx Rate | M10: Date | N10: Qty | O10: Rate Appx. | P10: Amount | Q10: Pending Qty | R10: Signature | S10: Pending Qty | T10: Signature
A11: 2 | B11: Tufnil (200mg) | C11: Pcs | D11: Tablet (10 mg) | E11: New | F11: Medical | G11: 60 | H11: =_xlfn.XLOOKUP(B11,'[1]Stock July-26'!$D:$D,'[1]Stock July-26'!$Q:$Q,0,0) -> 0 | I11: =ROUND(J11/26*3,0) -> 0 | J11: =_xlfn.XLOOKUP(B11,'[1]Stock June-26 '!$D:$D,'[1]Stock June-26 '!$O:$O,0,0) -> 0 | K11: 0 | L11: 0 | M11: 0 | N11: =(G11+I11)-H11 -> 60 | O11: =L11 -> 0 | P11: =N11*O11 -> 0
A12: 3 | B12: 2. Emistat (8mg) - 100 pcs | C12: Pcs | D12: Tablet (400 mg) | E12: New | F12: Medical | G12: 100 | H12: =_xlfn.XLOOKUP(B12,'[1]Stock July-26'!$D:$D,'[1]Stock July-26'!$Q:$Q,0,0) -> 0 | I12: =ROUND(J12/26*3,0) -> 0 | J12: =_xlfn.XLOOKUP(B12,'[1]Stock June-26 '!$D:$D,'[1]Stock June-26 '!$O:$O,0,0) -> 0 | K12: 0 | L12: 0 | M12: 0 | N12: =(G12+I12)-H12 -> 100 | O12: =L12 -> 0 | P12: =N12*O12 -> 0
A13: 1 | B13: 3. Napa Extra - 200 pcs | C13: Pcs | D13: Tablet (10 mg) | E13: New | F13: Medical | G13: 200 | H13: =_xlfn.XLOOKUP(B13,'[1]Stock July-26'!$D:$D,'[1]Stock July-26'!$Q:$Q,0,0) -> 0 | I13: =ROUND(J13/26*3,0) -> 0 | J13: =_xlfn.XLOOKUP(B13,'[1]Stock June-26 '!$D:$D,'[1]Stock June-26 '!$O:$O,0,0) -> 0 | K13: 0 | L13: 0 | M13: 0 | N13: =(G13+I13)-H13 -> 200 | O13: =L13 -> 0 | P13: =N13*O13 -> 0
A14: 2 | B14: 4. Napa (500mg) - 300 pcs | C14: Pcs | D14: Tablet (20 mg + 40 mg) | E14: New | F14: Medical | G14: 300 | H14: =_xlfn.XLOOKUP(B14,'[1]Stock July-26'!$D:$D,'[1]Stock July-26'!$Q:$Q,0,0) -> 0 | I14: =ROUND(J14/26*3,0) -> 0 | J14: =_xlfn.XLOOKUP(B14,'[1]Stock June-26 '!$D:$D,'[1]Stock June-26 '!$O:$O,0,0) -> 0 | K14: 0 | L14: 0 | M14: 0 | N14: =(G14+I14)-H14 -> 300 | O14: =L14 -> 0 | P14: =N14*O14 -> 0
A15: 3 | B15: 5. Entacyd Plus - 300 pcs | C15: Pcs | D15: Tablet (5 mg) | E15: New | F15: Medical | G15: 300 | H15: =_xlfn.XLOOKUP(B15,'[1]Stock July-26'!$D:$D,'[1]Stock July-26'!$Q:$Q,0,0) -> 0 | I15: =ROUND(J15/26*3,0) -> 0 | J15: =_xlfn.XLOOKUP(B15,'[1]Stock June-26 '!$D:$D,'[1]Stock June-26 '!$O:$O,0,0) -> 0 | K15: 0 | L15: 0 | M15: 0 | N15: =(G15+I15)-H15 -> 300 | O15: =L15 -> 0 | P15: =N15*O15 -> 0
A16: 1 | B16: 6. Myolax (50mg) - 50 pcs | C16: Pcs | D16: Tablet (8 mg) | E16: New | F16: Medical | G16: 50 | H16: =_xlfn.XLOOKUP(B16,'[1]Stock July-26'!$D:$D,'[1]Stock July-26'!$Q:$Q,0,0) -> 0 | I16: =ROUND(J16/26*3,0) -> 0 | J16: =_xlfn.XLOOKUP(B16,'[1]Stock June-26 '!$D:$D,'[1]Stock June-26 '!$O:$O,0,0) -> 0 | K16: 0 | L16: 0 | M16: 0 | N16: =(G16+I16)-H16 -> 50 | O16: =L16 -> 0 | P16: =N16*O16 -> 0
A17: 2 | B17: 7. Rolac (10mg) - 40 pcs | C17: Pcs | D17: Chewable Tablet | E17: New | F17: Medical | G17: 40 | H17: =_xlfn.XLOOKUP(B17,'[1]Stock July-26'!$D:$D,'[1]Stock July-26'!$Q:$Q,0,0) -> 0 | I17: =ROUND(J17/26*3,0) -> 0 | J17: =_xlfn.XLOOKUP(B17,'[1]Stock June-26 '!$D:$D,'[1]Stock June-26 '!$O:$O,0,0) -> 0 | K17: 0 | L17: 0 | M17: 0 | N17: =(G17+I17)-H17 -> 40 | O17: =L17 -> 0 | P17: =N17*O17 -> 0
A18: 3 | B18: 8. Algin (50mg) - 100 pcs | C18: Pcs | D18: Tablet (120 mg) | E18: New | F18: Medical | G18: 100 | H18: =_xlfn.XLOOKUP(B18,'[1]Stock July-26'!$D:$D,'[1]Stock July-26'!$Q:$Q,0,0) -> 0 | I18: =ROUND(J18/26*3,0) -> 0 | J18: =_xlfn.XLOOKUP(B18,'[1]Stock June-26 '!$D:$D,'[1]Stock June-26 '!$O:$O,0,0) -> 0 | K18: 0 | L18: 0 | M18: 0 | N18: =(G18+I18)-H18 -> 100 | O18: =L18 -> 0 | P18: =N18*O18 -> 0
A19: 1 | B19: 9. Flexi (100mg) - 100 pcs | C19: Pcs | D19: Tablet (100 mg) | E19: New | F19: Medical | G19: 100 | H19: =_xlfn.XLOOKUP(B19,'[1]Stock July-26'!$D:$D,'[1]Stock July-26'!$Q:$Q,0,0) -> 0 | I19: =ROUND(J19/26*3,0) -> 0 | J19: =_xlfn.XLOOKUP(B19,'[1]Stock June-26 '!$D:$D,'[1]Stock June-26 '!$O:$O,0,0) -> 0 | K19: 0 | L19: 0 | M19: 0 | N19: =(G19+I19)-H19 -> 100 | O19: =L19 -> 0 | P19: =N19*O19 -> 0
A20: 2 | B20: 10. Zimax (500mg) - 100 pcs | C20: Pcs | D20: Tablet (2 mg) | E20: New | F20: Medical | G20: 100 | H20: =_xlfn.XLOOKUP(B20,'[1]Stock July-26'!$D:$D,'[1]Stock July-26'!$Q:$Q,0,0) -> 0 | I20: =ROUND(J20/26*3,0) -> 0 | J20: =_xlfn.XLOOKUP(B20,'[1]Stock June-26 '!$D:$D,'[1]Stock June-26 '!$O:$O,0,0) -> 0 | K20: 0 | L20: 0 | M20: 0 | N20: =(G20+I20)-H20 -> 100 | O20: =L20 -> 0 | P20: =N20*O20 -> 0
A21: 3 | B21: 11. Etorix (120mg) - 100 pcs | C21: Pcs | D21: Tablet (20 mg) | E21: New | F21: Medical | G21: 100 | H21: =_xlfn.XLOOKUP(B21,'[1]Stock July-26'!$D:$D,'[1]Stock July-26'!$Q:$Q,0,0) -> 0 | I21: =ROUND(J21/26*3,0) -> 0 | J21: =_xlfn.XLOOKUP(B21,'[1]Stock June-26 '!$D:$D,'[1]Stock June-26 '!$O:$O,0,0) -> 0 | K21: 0 | L21: 0 | M21: 0 | N21: =(G21+I21)-H21 -> 100 | O21: =L21 -> 0 | P21: =N21*O21 -> 0
A22: 1 | B22: 12. ORS Saline - 8 box / 200 pcs | C22: Pcs | D22: Tablet (50 mg) | E22: New | F22: Medical | G22: 200 | H22: =_xlfn.XLOOKUP(B22,'[1]Stock July-26'!$D:$D,'[1]Stock July-26'!$Q:$Q,0,0) -> 0 | I22: =ROUND(J22/26*3,0) -> 0 | J22: =_xlfn.XLOOKUP(B22,'[1]Stock June-26 '!$D:$D,'[1]Stock June-26 '!$O:$O,0,0) -> 0 | K22: 0 | L22: 0 | M22: 0 | N22: =(G22+I22)-H22 -> 200 | O22: =L22 -> 0 | P22: =N22*O22 -> 0
... A27: 3 | B27: 17. Cotton (25g/packet) - 200 pcs | C27: Pcs | D27: Cream Tube | E27: New | F27: Medical | G27: 200 | H27: =_xlfn.XLOOKUP(B27,'[1]Stock July-26'!$D:$D,'[1]Stock July-26'!$Q:$Q,0,0) -> 0 | I27: =ROUND(J27/26*3,0) -> 0 | J27: =_xlfn.XLOOKUP(B27,'[1]Stock June-26 '!$D:$D,'[1]Stock June-26 '!$O:$O,0,0) -> 0 | K27: 0 | L27: 0 | M27: 0 | N27: =(G27+I27)-H27 -> 200 | O27: =L27 -> 0 | P27: =N27*O27 -> 0
A28: Total- | P28: =SUM(P11:P27) -> 0
B35: Prepared by | G35: Store | O35: Checked by | T35: Approved by

Sheet Needle
A1: Humana Apparels Pvt Ltd.
A2: Purchase Requisition
A3: Requisition No | E3: =ALL!E3 -> HAPL/Dept./ALL/2026/August/01 | N3: Store Personnel
A4: Requisition Date | E4: =ALL!E4 -> 46235 | N4: Md. Ebrahim
A5: Name of Unit | E5: =ALL!E5 -> Humana Apparels Pvt. Ltd. | N5: Sr. Executive
A6: Section | E6: =ALL!E6 -> ALL | N6: Store & Warehouse
A7: Name of User | E7: =ALL!E7 -> ALL | N7: 01839-004906
A8: Contact No. / Email | E8: =ALL!E8 -> amirul@humanaapparels.com | N8: ebrahim@humanaapparels.com
A9: SL | B9: Name of Item's | C9: Uom | D9: Specification / Brand & Model | E9: Type (Replace/ New) | F9: User Dept./ Section | G9: Stock Details | K9: Last Purchase Details | N9: To Be Procured | Q9: Store Acknowledgement on GRN | S9: Accounts Acknowledgment on Pmt | U9: Remarks
G10: Qty Requested | H10: Stock in Hand | I10: Saftey Stock | J10: Consumption (Last Month) | K10: Qty | L10: Approx Rate | M10: Date | N10: Qty | O10: Rate Appx. | P10: Amount | Q10: Pending Qty | R10: Signature | S10: Pending Qty | T10: Signature
A11: 1 | B11: P/M Needle DBX1-R-09 | C11: Pkt | E11: - | F11: Maintenance | G11: 220 | H11: 70 | I11: 20 | J11: 180 | K11: 150 | L11: 84 | M11: 46191 | N11: 170 | O11: 84 | P11: 14280
A12: 2 | B12: T/N Needle DPX5-R-11 | C12: Pkt | E12: - | F12: Maintenance | G12: 60 | H12: 13 | I12: 3 | J12: 23 | K12: 20 | L12: 84 | M12: 46191 | N12: 50 | O12: 84 | P12: 4200
A13: Total- | P13: =SUM(P11:P12) -> 18480
B21: Prepared by | G21: Store | O21: Checked by | T21: Approved by

Sheet Spare Parts
A1: Humana Apparels Pvt Ltd.
A2: Purchase Requisition
A3: Requisition No | E3: =ALL!E3 -> HAPL/Dept./ALL/2026/August/01 | N3: Store Personnel
A4: Requisition Date | E4: =ALL!E4 -> 46235 | N4: Md. Ebrahim
A5: Name of Unit | E5: =ALL!E5 -> Humana Apparels Pvt. Ltd. | N5: Sr. Executive
A6: Section | E6: =ALL!E6 -> ALL | N6: Store & Warehouse
A7: Name of User | E7: =ALL!E7 -> ALL | N7: 01839-004906
A8: Contact No. / Email | E8: =ALL!E8 -> amirul@humanaapparels.com | N8: ebrahim@humanaapparels.com
A9: SL | B9: Name of Item's | C9: Uom | D9: Specification / Brand & Model | E9: Type (Replace/ New) | F9: User Dept./ Section | G9: Stock Details | K9: Last Purchase Details | N9: To Be Procured | Q9: Store Acknowledgement on GRN | S9: Accounts Acknowledgment on Pmt | U9: Remarks
G10: Qty Requested | H10: Stock in Hand | I10: Saftey Stock | J10: Consumption (Last Month) | K10: Qty | L10: Approx Rate | M10: Date | N10: Qty | O10: Rate Appx. | P10: Amount | Q10: Pending Qty | R10: Signature | S10: Pending Qty | T10: Signature
A11: 1 | B11: Scissors QX-10" | C11: Pcs | E11: - | F11: Production | G11: 12 | H11: 7 | I11: 1 | J11: 10 | K11: 6 | L11: 368 | M11: 46222 | N11: 5 | O11: 368 | P11: 1840
A12: 2 | B12: Thread Cutter | C12: Pcs | E12: - | F12: All | G12: 450 | H12: 50 | I12: 59 | J12: 509 | K12: 540 | L12: 14.5 | M12: 46222 | N12: 400 | O12: 14.5 | P12: 5800
A13: 3 | B13: P/M Plastic Plain Feet | C13: Pcs | E13: - | F13: Production | G13: 300 | H13: 110 | I13: 24 | J13: 206 | K13: 186 | L13: 16 | M13: 46203 | N13: 190 | O13: 16 | P13: 3040
A14: 4 | B14: P/M Plastic Zipper Guide-Both | C14: Pcs | E14: - | F14: Production | G14: 100 | H14: 59 | I14: 7 | J14: 60 | K14: 350 | L14: 18 | M14: 46079 | N14: 41 | O14: 18 | P14: 738
A15: 5 | B15: Anty Cutter-18mm | C15: Pcs | E15: - | F15: Production | G15: 5 | H15: 3 | I15: 1 | J15: 5 | K15: 4 | L15: 75 | M15: 46221 | N15: 2 | O15: 75 | P15: 150
A16: 6 | B16: Rubban Tin | C16: Pcs | E16: - | F16: Production | G16: 48 | H16: 28 | I16: 4 | J16: 38 | K16: 22 | L16: 70 | M16: 46222 | N16: 20 | O16: 70 | P16: 1400
A17: 7 | B17: Drill machine battery | C17: Pcs | E17: - | F17: Production | G17: 2 | H17: 0 | I17: 0 | J17: 0 | K17: 0 | L17: 0 | M17: 0 | N17: 2 | O17: 0 | P17: 0
A18: 8 | B18: Machine Oil-32 Grade | C18: Ltr | E18: - | F18: Maintenance | G18: 20 | H18: 0 | I18: 2 | J18: 20 | K18: 20 | L18: 340 | M18: 46211 | N18: 20 | O18: 340 | P18: 6800
A19: 9 | B19: B/T Eye Glass | C19: Pcs | D19: Juki LK-1900SSS000-A | E19: - | F19: Maintenance | G19: 15 | H19: 0 | I19: 2 | J19: 19 | K19: 37 | L19: 20 | M19: 46167 | N19: 15 | O19: 20 | P19: 300
A20: 10 | B20: B/T Eye Glass-Juki | C20: Pcs | D20: Barther KE-430DP-03 | E20: New | F20: Maintenance | G20: 15 | H20: 0 | I20: 0 | J20: 0 | K20: 0 | L20: 0 | M20: 0 | N20: 15 | O20: 0 | P20: 0
A21: 11 | B21: Cutting Machine Knife Screw | C21: Pcs | E21: - | F21: Maintenance | G21: 10 | H21: 0 | I21: 1 | J21: 10 | K21: 10 | L21: 25 | M21: 46210 | N21: 10 | O21: 25 | P21: 250
A22: 12 | B22: Combination Spanner-07mm | C22: Pcs | D22: 7.8.9.10.11.12 | E22: - | F22: Maintenance | G22: 5 | H22: 0 | I22: 0 | J22: 0 | K22: 6 | L22: 140 | M22: 45635 | N22: 5 | O22: 140 | P22: 700
A23: 13 | B23: Combination Spanner-08mm | C23: Pcs | E23: - | F23: Maintenance | G23: 5 | H23: 0 | I23: 0 | J23: 0 | K23: 6 | L23: 150 | M23: 45635 | N23: 5 | O23: 150 | P23: 750
A24: 14 | B24: Combination Spanner-12mm | C24: Pcs | E24: - | F24: Maintenance | G24: 5 | H24: 0 | I24: 0 | J24: 0 | K24: 0 | L24: 0 | M24: 0 | N24: 5 | O24: 0 | P24: 0
A25: 15 | B25: Combination Spanner-10mm | C25: Pcs | E25: - | F25: Maintenance | G25: 5 | H25: 0 | I25: 0 | J25: 0 | K25: 1 | L25: 170 | M25: 45635 | N25: 5 | O25: 170 | P25: 850
A26: 16 | B26: Combination Spanner-11mm | C26: Pcs | E26: - | F26: Maintenance | G26: 5 | H26: 0 | I26: 0 | J26: 0 | K26: 1 | L26: 170 | M26: 45635 | N26: 5 | O26: 170 | P26: 850
A27: 17 | B27: P/M Auto Bobbin Winder Rubber | C27: Pcs | D27: Balck | E27: - | F27: Maintenance | G27: 30 | H27: 0 | I27: 2 | J27: 15 | K27: 15 | L27: 10 | M27: 46203 | N27: 30 | O27: 10 | P27: 300
A28: 18 | B28: F/L Loop Folder-24mm-12mm | C28: Pcs | D28: Inpout-24mm Outpout-12mm | E28: New | F28: Maintenance | G28: 2 | H28: 0 | I28: 0 | J28: 1 | K28: 1 | L28: 600 | M28: 46219 | N28: 2 | O28: 600 | P28: 1200
A29: 19 | B29: B/T Machine Sattel-Juki | C29: Pcs | D29: Juki LK-1900SSS000-A | E29: - | F29: Maintenance | G29: 5 | H29: 0 | I29: 0 | J29: 0 | K29: 5 | L29: 650 | M29: 46119 | N29: 5 | O29: 650 | P29: 3250
A30: 20 | B30: B/T Machine Sattel-Brother | C30: Pcs | D30: Brother KE-430DP-03 | E30: - | F30: Maintenance | G30: 5 | H30: 0 | I30: 0 | J30: 0 | K30: 5 | L30: 650 | M30: 46119 | N30: 5 | O30: 650 | P30: 3250
A31: 21 | B31: B/T Machine Ring-Juki | C31: Pcs | D31: Juki LK-1900SSS000-A | E31: - | F31: Maintenance | G31: 5 | H31: 0 | I31: 0 | J31: 0 | K31: 5 | L31: 850 | M31: 46119 | N31: 5 | O31: 850 | P31: 4250
A32: 22 | B32: P/M Plastic Guide 1/16 CR | C32: Pcs | E32: - | F32: Maintenance | G32: 150 | H32: 0 | I32: 5 | J32: 40 | K32: 100 | L32: 19 | M32: 46203 | N32: 150 | O32: 19 | P32: 2850
A33: 23 | B33: B/T Machine Ring-Brother | C33: Pcs | D33: Brother KE-430DP-03 | E33: - | F33: Maintenance | G33: 5 | H33: 0 | I33: 0 | J33: 0 | K33: 5 | L33: 450 | M33: 46119 | N33: 5 | O33: 450 | P33: 2250
A34: 24 | B34: 500ml Siliconi Silicone | C34: Pcs | E34: New | F34: Maintenance | G34: 2 | H34: 0 | I34: 0 | J34: 0 | K34: 0 | L34: 0 | M34: 0 | N34: 2 | O34: 0 | P34: 0
A35: 25 | B35: P/M Tension Pust Spring | C35: Pcs | D35: Juki-DDL-900C 40263455 | E35: - | F35: Maintenance | G35: 2 | H35: 0 | I35: 0 | J35: 0 | K35: 5 | L35: 5 | M35: 46167 | N35: 2 | O35: 5 | P35: 10
A36: 26 | B36: Pvc Pipe-3/4'' | C36: Pcs | D36: White | E36: - | F36: Maintenance | G36: 30 | H36: 0 | I36: 4 | J36: 36 | K36: 7 | L36: 118 | M36: 46215 | N36: 30 | O36: 118 | P36: 3540
A37: 27 | B37: Metal Flexible Pipe 1/2" | C37: Coil | E37: - | F37: Maintenance | G37: 3 | H37: 0 | I37: 0 | J37: 1 | K37: 1 | L37: 2400 | M37: 46202 | N37: 3 | O37: 2400 | P37: 7200
A38: 28 | B38: Pvc Elbow-3/4" | C38: Pcs | D38: White | E38: - | F38: Maintenance | G38: 50 | H38: 40 | I38: 2 | J38: 20 | K38: 30 | L38: 16 | M38: 46215 | N38: 10 | O38: 16 | P38: 160
A39: 29 | B39: Ceiling Fan Capacitor 2.5MF | C39: Pcs | D39: 2.5MF | E39: - | F39: Maintenance | G39: 10 | H39: 1 | I39: 0 | J39: 0 | K39: 1 | L39: 100 | M39: 46163 | N39: 9 | O39: 100 | P39: 900
A40: 30 | B40: Quilting M/C DC LED light | C40: Pcs | D40: 24V | E40: New | F40: Maintenance | G40: 10 | H40: 0 | I40: 0 | J40: 0 | K40: 0 | L40: 0 | M40: 0 | N40: 10 | O40: 0 | P40: 0
...

Sheet Chemical
A1: Humana Apparels Pvt Ltd.
A2: Purchase Requisition
A3: Requisition No | E3: =ALL!E3 -> HAPL/Dept./ALL/2026/August/01 | N3: Store Personnel
A4: Requisition Date | E4: =ALL!E4 -> 46235 | N4: Md. Ebrahim
A5: Name of Unit | E5: =ALL!E5 -> Humana Apparels Pvt. Ltd. | N5: Sr. Executive
A6: Section | E6: =ALL!E6 -> ALL | N6: Store & Warehouse
A7: Name of User | E7: =ALL!E7 -> ALL | N7: 01839-004906
A8: Contact No. / Email | E8: =ALL!E8 -> amirul@humanaapparels.com | N8: ebrahim@humanaapparels.com
A9: SL | B9: Name of Item's | C9: Uom | D9: Specification / Brand & Model | E9: Type (Replace/ New) | F9: User Dept./ Section | G9: Stock Details | K9: Last Purchase Details | N9: To Be Procured | Q9: Store Acknowledgement on GRN | S9: Accounts Acknowledgment on Pmt | U9: Remarks
G10: Qty Requested | H10: Stock in Hand | I10: Saftey Stock | J10: Consumption (Last Month) | K10: Qty | L10: Approx Rate | M10: Date | N10: Qty | O10: Rate Appx. | P10: Amount | Q10: Pending Qty | R10: Signature | S10: Pending Qty | T10: Signature
A11: 1 | B11: NC Thinner | C11: Ltr | E11: - | F11: HR | G11: 8 | H11: 0 | I11: 1 | J11: 8 | K11: 5 | L11: 250 | M11: 46221 | N11: 8 | O11: 250 | P11: 2000
A12: 2 | B12: Chemical-ISV 250ml | C12: Pcs | E12: - | F12: Finishing | G12: 70 | H12: 0 | I12: 4 | J12: 33 | K12: 63 | L12: 238 | M12: 46198 | N12: 70 | O12: 238 | P12: 16660
A13: 3 | B13: Chemical- Panil 250ml | C13: Pcs | E13: - | F13: Finishing | G13: 50 | H13: 0 | I13: 1 | J13: 5 | K13: 50 | L13: 487 | M13: 46148 | N13: 50 | O13: 487 | P13: 24350
A14: 4 | B14: Chemical-PSV Plus 250ml | C14: Pcs | E14: - | F14: Finishing | G14: 40 | H14: 0 | I14: 0 | J14: 0 | K14: 14 | L14: 440 | M14: 46198 | N14: 40 | O14: 440 | P14: 17600
A15: 5 | B15: Chemical-B.P.S | C15: Pcs | E15: - | F15: Finishing | G15: 60 | H15: 0 | I15: 5 | J15: 41 | K15: 2 | L15: 315 | M15: 45966 | N15: 60 | O15: 315 | P15: 18900
A16: 6 | B16: Chemical-Print Clean | C16: Pcs | E16: - | F16: Finishing | G16: 40 | H16: 0 | I16: 0 | J16: 0 | K16: 5 | L16: 360 | M16: 45847 | N16: 40 | O16: 360 | P16: 14400
A17: 7 | B17: CNR | C17: pcs | E17: New | F17: Finishing | G17: 30 | H17: 0 | I17: 0 | J17: 0 | K17: 0 | L17: 0 | M17: 0 | N17: 30 | O17: 0 | P17: 0
A18: 8 | B18: Chemical HP-10 | C18: Pcs | E18: - | F18: Finishing | G18: 20 | H18: 0 | I18: 0 | J18: 0 | K18: 4 | L18: 405 | M18: 45839 | N18: 20 | O18: 405 | P18: 8100
A19: 9 | B19: Chemical-Oil Remover 01 Ltr | C19: Pcs | E19: - | F19: Finishing | G19: 30 | H19: 0 | I19: 0 | J19: 0 | K19: 10 | L19: 422.5 | M19: 45865 | N19: 30 | O19: 422.5 | P19: 12675
A20: 10 | B20: Spot Lifter 833-400ml | C20: Pcs | E20: - | F20: Finishing | G20: 150 | H20: 132 | I20: 10 | J20: 87 | K20: 171 | L20: 384 | M20: 46221 | N20: 18 | O20: 384 | P20: 6912
A21: Total- | P21: =SUM(P11:P20) -> 121597
B30: Prepared by | G30: Store | O30: Checked by | T30: Approved by
